<?xml version="1.0" ?>
<robot name="M445">
  <link name="BASE">
    <visual name="">
      <origin rpy="0 0.0 0.0" xyz="0.0 0.0 0.0"/>
      <geometry>
        <mesh filename="meshes/BASE.dae" scale="1.0 1.0 1.0"/>
      </geometry>
    </visual>
  </link>
  <link name="BASE_INERTIA">
    <inertial>
      <origin rpy="0.0 0.0 0.0" xyz="0.0 0.0 0.2597"/>
      <mass value="1035.0"/>
      <inertia ixx="444.014" ixy="-0.812009" ixz="0.599566" iyy="216.335" iyz="-0.539448" izz="580.445"/>
    </inertial>
  </link>
  <joint name="base_inertia_link" type="fixed">
    <origin rpy="0 0 0" xyz="0.0 0.0 0.0"/>
    <parent link="BASE"/>
    <child link="BASE_INERTIA"/>
  </joint>
  <link name="LF_SWIVEL">
    <inertial>
      <origin xyz="0.05 0.0 0.223"/>
      <mass value="152"/>
      <inertia ixx="11.3112" ixy="-0.00029176" ixz="0.834006" iyy="13.0582" iyz="-0.000342744" izz="2.9062"/>
    </inertial>
    <visual name="">
      <origin xyz="0.0 0.0 0.0"/>
      <geometry>
        <mesh filename="meshes/SWIVEL.dae" scale="1.0 1.0 1.0"/>
      </geometry>
      <material name="">
        <color rgba="1.0 0.0 0.0 1.0"/>
      </material>
    </visual>
    <collision>
      <origin xyz="0.0 0.0 0.0"/>
      <geometry>
        <mesh filename="meshes/SWIVEL.dae" scale="1.0 1.0 1.0"/>
      </geometry>
    </collision>
  </link>
  <joint name="J_LF_HAA" type="fixed">
    <origin rpy="0.0 0.0 0" xyz="0.566 0.751 0.05"/>
    <parent link="BASE"/>
    <child link="LF_SWIVEL"/>
  </joint>
  <link name="RF_SWIVEL">
    <inertial>
      <origin xyz="0.05 0.0 0.223"/>
      <mass value="152"/>
      <inertia ixx="11.3112" ixy="-0.00029176" ixz="0.834006" iyy="13.0582" iyz="-0.000342744" izz="2.9062"/>
    </inertial>
    <visual name="">
      <origin xyz="0.0 0.0 0.0"/>
      <geometry>
        <mesh filename="meshes/SWIVEL.dae" scale="1.0 1.0 1.0"/>
      </geometry>
      <material name="">
        <color rgba="1.0 0.0 0.0 1.0"/>
      </material>
    </visual>
    <collision>
      <origin xyz="0.0 0.0 0.0"/>
      <geometry>
        <mesh filename="meshes/SWIVEL.dae" scale="1.0 1.0 1.0"/>
      </geometry>
    </collision>
  </link>
  <joint name="J_RF_HAA" type="fixed">
    <origin rpy="0.0 0.0 0" xyz="0.566 -0.751 0.05"/>
    <parent link="BASE"/>
    <child link="RF_SWIVEL"/>
  </joint>
  <link name="LH_SWIVEL">
    <inertial>
      <origin xyz="0.05 0.0 0.223"/>
      <mass value="152"/>
      <inertia ixx="11.3112" ixy="-0.00029176" ixz="0.834006" iyy="13.0582" iyz="-0.000342744" izz="2.9062"/>
    </inertial>
    <visual name="">
      <origin xyz="0.0 0.0 0.0"/>
      <geometry>
        <mesh filename="meshes/SWIVEL.dae" scale="1.0 1.0 1.0"/>
      </geometry>
      <material name="">
        <color rgba="1.0 0.0 0.0 1.0"/>
      </material>
    </visual>
  </link>
  <joint name="J_LH_HAA" type="fixed">
    <origin rpy="0.0 0.0 3.1415" xyz="-0.566 0.751 0.05"/>
    <parent link="BASE"/>
    <child link="LH_SWIVEL"/>
  </joint>
  <link name="RH_SWIVEL">
    <inertial>
      <origin xyz="0.05 0.0 0.223"/>
      <mass value="152"/>
      <inertia ixx="11.3112" ixy="-0.00029176" ixz="0.834006" iyy="13.0582" iyz="-0.000342744" izz="2.9062"/>
    </inertial>
    <visual name="">
      <origin xyz="0.0 0.0 0.0"/>
      <geometry>
        <mesh filename="meshes/SWIVEL.dae" scale="1.0 1.0 1.0"/>
      </geometry>
      <material name="">
        <color rgba="1.0 0.0 0.0 1.0"/>
      </material>
    </visual>
  </link>
  <joint name="J_RH_HAA" type="fixed">
    <origin rpy="0.0 0.0 3.1415" xyz="-0.566 -0.751 0.05"/>
    <parent link="BASE"/>
    <child link="RH_SWIVEL"/>
  </joint>
  <link name="LF_LEG">
    <inertial>
      <origin xyz="0.689 0.014 -0.018"/>
      <mass value="200.0"/>
      <inertia ixx="3.5061" ixy="2.18666" ixz="-1.56998" iyy="137.358" iyz="-0.087766" izz="137.573"/>
    </inertial>
    <visual name="">
      <origin xyz="0.0 0.0 0.0"/>
      <geometry>
        <mesh filename="meshes/LEG.dae" scale="1 1 1"/>
      </geometry>
      <material name="test">
        <color rgba="1.0 0.0 0.0 1.0"/>
      </material>
    </visual>
    <collision>
      <origin xyz="0.0 0.0 0.0"/>
      <geometry>
        <mesh filename="meshes/LEG.dae" scale="1 1 1"/>
      </geometry>
    </collision>
  </link>
  <joint name="J_LF_HFE" type="fixed">
    <origin rpy="0 0 0" xyz="0.175 0.0 0.03"/>
    <parent link="LF_SWIVEL"/>
    <child link="LF_LEG"/>
  </joint>
  <link name="LF_PARALLEL">
    <inertial>
      <origin xyz="0.655 -0.02 0.017"/>
      <mass value="57.8"/>
      <inertia ixx="0.491418" ixy="-1.3961" ixz="0.62413" iyy="36.905" iyz="-0.0098" izz="37.279"/>
    </inertial>
    <visual name="">
      <origin xyz="0.0 0.0 0.0"/>
      <geometry>
        <mesh filename="meshes/PARALLEL.dae" scale="1 1 1"/>
      </geometry>
      <material name="test">
        <color rgba="1.0 0.0 0.0 1.0"/>
        <texture filename=""/>
      </material>
    </visual>
    <collision>
      <origin xyz="0.0 0.0 0.0"/>
      <geometry>
        <mesh filename="meshes/PARALLEL.dae" scale="1 1 1"/>
      </geometry>
    </collision>
  </link>
  <joint name="J_LF_PARALLEL1" type="fixed">
    <origin xyz="0.231 0.0 0.350"/>
    <parent link="LF_SWIVEL"/>
    <child link="LF_PARALLEL"/>
  </joint>
  <link name="LF_KNUCKLE">
    <inertial>
      <origin xyz="0.130 0.063 0.112"/>
      <mass value="125.0"/>
      <inertia ixx="8.10054" ixy="-0.598212" ixz="2.18602" iyy="7.48234" iyz="-0.131793" izz="7.10409"/>
    </inertial>
    <visual name="">
      <origin xyz="0.0 0.0 0.0"/>
      <geometry>
        <mesh filename="meshes/KNUCKLE.dae" scale="1 1 1"/>
      </geometry>
      <material name="">
        <color rgba="1.0 0.0 0.0 1.0"/>
        <texture filename=""/>
      </material>
    </visual>
    <collision>
      <origin xyz="0.0 0.0 0.0"/>
      <geometry>
        <mesh filename="meshes/KNUCKLE.dae" scale="1 1 1"/>
      </geometry>
    </collision>
  </link>
  <joint name="J_LF_PARALLEL2" type="fixed">
    <origin xyz="1.424 0.0125 0.0"/>
    <parent link="LF_LEG"/>
    <child link="LF_KNUCKLE"/>
  </joint>
  <link name="LF_MOTOR">
    <inertial>
      <origin xyz="0.137 0.0 -0.012"/>
      <mass value="135.0"/>
      <inertia ixx="2.7945" ixy="0.0284" ixz="0.1825" iyy="5.1558" iyz="0.1494" izz="4.7264"/>
    </inertial>
    <visual>
      <origin xyz="0.0 0.0 0.0"/>
      <geometry>
        <mesh filename="meshes/MOTOR.dae" scale="1.0 1.0 1.0"/>
      </geometry>
    </visual>
    <collision>
      <origin xyz="0.0 0.0 0.0"/>
      <geometry>
        <mesh filename="meshes/MOTOR.dae" scale="1.0 1.0 1.0"/>
      </geometry>
    </collision>
  </link>
  <joint name="J_LF_STEER" type="fixed">
    <origin rpy="0.0 0.0 1.5707963267948966" xyz="0.05 0.3835 0.051"/>
    <parent link="LF_KNUCKLE"/>
    <child link="LF_MOTOR"/>
  </joint>
  <link name="LF_WHEEL">
    <inertial>
      <origin xyz="0.02 0.0 0.0"/>
      <mass value="420"/>
      <inertia ixx="72.4592" ixy="-0.0173" ixz="-0.0116" iyy="48.4413" iyz="0.017" izz="48.4413"/>
    </inertial>
    <visual>
      <origin xyz="0.0 0.0 0.0"/>
      <geometry>
        <mesh filename="meshes/WHEEL.dae" scale="1.0 1.0 1.0"/>
      </geometry>
      <material name="">
        <color rgba="1.0 0.0 0.0 1.0"/>
      </material>
    </visual>
    <collision>
      <origin xyz="0.0 0.0 0.0"/>
      <geometry>
        <sphere radius="0.6149438"/>
      </geometry>
    </collision>
  </link>
  <joint name="J_LF_WHEEL" type="fixed">
    <origin xyz="0.298 0.0 0.0"/>
    <parent link="LF_MOTOR"/>
    <child link="LF_WHEEL"/>
  </joint>
  <link name="RF_LEG">
    <inertial>
      <origin xyz="0.689 0.014 -0.018"/>
      <mass value="200.0"/>
      <inertia ixx="3.5061" ixy="2.18666" ixz="-1.56998" iyy="137.358" iyz="-0.087766" izz="137.573"/>
    </inertial>
    <visual name="">
      <origin xyz="0.0 0.0 0.0"/>
      <geometry>
        <mesh filename="meshes/LEG.dae" scale="1 -1 1"/>
      </geometry>
      <material name="test">
        <color rgba="1.0 0.0 0.0 1.0"/>
      </material>
    </visual>
    <collision>
      <origin xyz="0.0 0.0 0.0"/>
      <geometry>
        <mesh filename="meshes/LEG.dae" scale="1 -1 1"/>
      </geometry>
    </collision>
  </link>
  <joint name="J_RF_HFE" type="fixed">
    <origin rpy="0 0 0" xyz="0.175 0.0 0.03"/>
    <parent link="RF_SWIVEL"/>
    <child link="RF_LEG"/>
  </joint>
  <link name="RF_PARALLEL">
    <inertial>
      <origin xyz="0.655 -0.02 0.017"/>
      <mass value="57.8"/>
      <inertia ixx="0.491418" ixy="-1.3961" ixz="0.62413" iyy="36.905" iyz="-0.0098" izz="37.279"/>
    </inertial>
    <visual name="">
      <origin xyz="0.0 0.0 0.0"/>
      <geometry>
        <mesh filename="meshes/PARALLEL.dae" scale="1 -1 1"/>
      </geometry>
      <material name="test">
        <color rgba="1.0 0.0 0.0 1.0"/>
        <texture filename=""/>
      </material>
    </visual>
    <collision>
      <origin xyz="0.0 0.0 0.0"/>
      <geometry>
        <mesh filename="meshes/PARALLEL.dae" scale="1 -1 1"/>
      </geometry>
    </collision>
  </link>
  <joint name="J_RF_PARALLEL1" type="fixed">
    <origin xyz="0.231 0.0 0.350"/>
    <parent link="RF_SWIVEL"/>
    <child link="RF_PARALLEL"/>
  </joint>
  <link name="RF_KNUCKLE">
    <inertial>
      <origin xyz="0.130 0.063 0.112"/>
      <mass value="125.0"/>
      <inertia ixx="8.10054" ixy="-0.598212" ixz="2.18602" iyy="7.48234" iyz="-0.131793" izz="7.10409"/>
    </inertial>
    <visual name="">
      <origin xyz="0.0 0.0 0.0"/>
      <geometry>
        <mesh filename="meshes/KNUCKLE.dae" scale="1 -1 1"/>
      </geometry>
      <material name="">
        <color rgba="1.0 0.0 0.0 1.0"/>
        <texture filename=""/>
      </material>
    </visual>
    <collision>
      <origin xyz="0.0 0.0 0.0"/>
      <geometry>
        <mesh filename="meshes/KNUCKLE.dae" scale="1 -1 1"/>
      </geometry>
    </collision>
  </link>
  <joint name="J_RF_PARALLEL2" type="fixed">
    <origin xyz="1.424 0.0125 0.0"/>
    <parent link="RF_LEG"/>
    <child link="RF_KNUCKLE"/>
  </joint>
  <link name="RF_MOTOR">
    <inertial>
      <origin xyz="0.137 0.0 -0.012"/>
      <mass value="135.0"/>
      <inertia ixx="2.7945" ixy="0.0284" ixz="0.1825" iyy="5.1558" iyz="0.1494" izz="4.7264"/>
    </inertial>
    <visual>
      <origin xyz="0.0 0.0 0.0"/>
      <geometry>
        <mesh filename="meshes/MOTOR.dae" scale="1.0 1.0 1.0"/>
      </geometry>
    </visual>
    <collision>
      <origin xyz="0.0 0.0 0.0"/>
      <geometry>
        <mesh filename="meshes/MOTOR.dae" scale="1.0 1.0 1.0"/>
      </geometry>
    </collision>
  </link>
  <joint name="J_RF_STEER" type="fixed">
    <origin rpy="0.0 0.0 -1.5707963267948966" xyz="0.05 -0.3835 0.051"/>
    <parent link="RF_KNUCKLE"/>
    <child link="RF_MOTOR"/>
  </joint>
  <link name="RF_WHEEL">
    <inertial>
      <origin xyz="0.02 0.0 0.0"/>
      <mass value="420"/>
      <inertia ixx="72.4592" ixy="-0.0173" ixz="-0.0116" iyy="48.4413" iyz="0.017" izz="48.4413"/>
    </inertial>
    <visual>
      <origin xyz="0.0 0.0 0.0"/>
      <geometry>
        <mesh filename="meshes/WHEEL.dae" scale="1.0 1.0 1.0"/>
      </geometry>
      <material name="">
        <color rgba="1.0 0.0 0.0 1.0"/>
      </material>
    </visual>
    <collision>
      <origin xyz="0.0 0.0 0.0"/>
      <geometry>
        <sphere radius="0.6149438"/>
      </geometry>
    </collision>
  </link>
  <joint name="J_RF_WHEEL" type="fixed">
    <origin xyz="0.298 0.0 0.0"/>
    <parent link="RF_MOTOR"/>
    <child link="RF_WHEEL"/>
  </joint>
  <link name="LH_LEG">
    <inertial>
      <origin xyz="0.689 0.014 -0.018"/>
      <mass value="200.0"/>
      <inertia ixx="3.5061" ixy="2.18666" ixz="-1.56998" iyy="137.358" iyz="-0.087766" izz="137.573"/>
    </inertial>
    <visual name="">
      <origin xyz="0.0 0.0 0.0"/>
      <geometry>
        <mesh filename="meshes/LEG.dae" scale="1 -1 1"/>
      </geometry>
      <material name="test">
        <color rgba="1.0 0.0 0.0 1.0"/>
      </material>
    </visual>
  </link>
  <joint name="J_LH_HFE" type="fixed">
    <origin rpy="0 0 0" xyz="0.175 0.0 0.03"/>
    <parent link="LH_SWIVEL"/>
    <child link="LH_LEG"/>
  </joint>
  <link name="LH_PARALLEL">
    <inertial>
      <origin xyz="0.655 -0.02 0.017"/>
      <mass value="57.8"/>
      <inertia ixx="0.491418" ixy="-1.3961" ixz="0.62413" iyy="36.905" iyz="-0.0098" izz="37.279"/>
    </inertial>
    <visual name="">
      <origin xyz="0.0 0.0 0.0"/>
      <geometry>
        <mesh filename="meshes/PARALLEL.dae" scale="1 -1 1"/>
      </geometry>
      <material name="test">
        <color rgba="1.0 0.0 0.0 1.0"/>
        <texture filename=""/>
      </material>
    </visual>
  </link>
  <joint name="J_LH_PARALLEL1" type="fixed">
    <origin xyz="0.231 0.0 0.350"/>
    <parent link="LH_SWIVEL"/>
    <child link="LH_PARALLEL"/>
  </joint>
  <link name="LH_KNUCKLE">
    <inertial>
      <origin xyz="0.130 0.063 0.112"/>
      <mass value="125.0"/>
      <inertia ixx="8.10054" ixy="-0.598212" ixz="2.18602" iyy="7.48234" iyz="-0.131793" izz="7.10409"/>
    </inertial>
    <visual name="">
      <origin xyz="0.0 0.0 0.0"/>
      <geometry>
        <mesh filename="meshes/KNUCKLE_BACK.dae" scale="1 -1 1"/>
      </geometry>
      <material name="">
        <color rgba="1.0 0.0 0.0 1.0"/>
        <texture filename=""/>
      </material>
    </visual>
  </link>
  <joint name="J_LH_PARALLEL2" type="fixed">
    <origin xyz="1.424 0.0125 0.0"/>
    <parent link="LH_LEG"/>
    <child link="LH_KNUCKLE"/>
  </joint>
  <link name="LH_MOTOR">
    <inertial>
      <origin xyz="0.137 0.0 -0.012"/>
      <mass value="135.0"/>
      <inertia ixx="2.7945" ixy="0.0284" ixz="0.1825" iyy="5.1558" iyz="0.1494" izz="4.7264"/>
    </inertial>
    <visual>
      <origin xyz="0.0 0.0 0.0"/>
      <geometry>
        <mesh filename="meshes/MOTOR.dae" scale="1.0 1.0 1.0"/>
      </geometry>
    </visual>
  </link>
  <joint name="J_LH_STEER" type="fixed">
    <origin rpy="0.0 0.0 -1.5707963267948966" xyz="0.05 -0.3835 0.051"/>
    <parent link="LH_KNUCKLE"/>
    <child link="LH_MOTOR"/>
  </joint>
  <link name="LH_WHEEL">
    <inertial>
      <origin xyz="0.02 0.0 0.0"/>
      <mass value="420"/>
      <inertia ixx="72.4592" ixy="-0.0173" ixz="-0.0116" iyy="48.4413" iyz="0.017" izz="48.4413"/>
    </inertial>
    <visual>
      <origin xyz="0.0 0.0 0.0"/>
      <geometry>
        <mesh filename="meshes/WHEEL.dae" scale="1.0 1.0 1.0"/>
      </geometry>
      <material name="">
        <color rgba="1.0 0.0 0.0 1.0"/>
      </material>
    </visual>
    <collision>
      <origin xyz="0.0 0.0 0.0"/>
      <geometry>
        <sphere radius="0.6149438"/>
      </geometry>
    </collision>
  </link>
  <joint name="J_LH_WHEEL" type="fixed">
    <origin xyz="0.298 0.0 0.0"/>
    <parent link="LH_MOTOR"/>
    <child link="LH_WHEEL"/>
  </joint>
  <link name="RH_LEG">
    <inertial>
      <origin xyz="0.689 0.014 -0.018"/>
      <mass value="200.0"/>
      <inertia ixx="3.5061" ixy="2.18666" ixz="-1.56998" iyy="137.358" iyz="-0.087766" izz="137.573"/>
    </inertial>
    <visual name="">
      <origin xyz="0.0 0.0 0.0"/>
      <geometry>
        <mesh filename="meshes/LEG.dae" scale="1 1 1"/>
      </geometry>
      <material name="test">
        <color rgba="1.0 0.0 0.0 1.0"/>
      </material>
    </visual>
  </link>
  <joint name="J_RH_HFE" type="fixed">
    <origin rpy="0 0 0" xyz="0.175 0.0 0.03"/>
    <parent link="RH_SWIVEL"/>
    <child link="RH_LEG"/>
  </joint>
  <link name="RH_PARALLEL">
    <inertial>
      <origin xyz="0.655 -0.02 0.017"/>
      <mass value="57.8"/>
      <inertia ixx="0.491418" ixy="-1.3961" ixz="0.62413" iyy="36.905" iyz="-0.0098" izz="37.279"/>
    </inertial>
    <visual name="">
      <origin xyz="0.0 0.0 0.0"/>
      <geometry>
        <mesh filename="meshes/PARALLEL.dae" scale="1 1 1"/>
      </geometry>
      <material name="test">
        <color rgba="1.0 0.0 0.0 1.0"/>
        <texture filename=""/>
      </material>
    </visual>
  </link>
  <joint name="J_RH_PARALLEL1" type="fixed">
    <origin xyz="0.231 0.0 0.350"/>
    <parent link="RH_SWIVEL"/>
    <child link="RH_PARALLEL"/>
  </joint>
  <link name="RH_KNUCKLE">
    <inertial>
      <origin xyz="0.130 0.063 0.112"/>
      <mass value="125.0"/>
      <inertia ixx="8.10054" ixy="-0.598212" ixz="2.18602" iyy="7.48234" iyz="-0.131793" izz="7.10409"/>
    </inertial>
    <visual name="">
      <origin xyz="0.0 0.0 0.0"/>
      <geometry>
        <mesh filename="meshes/KNUCKLE_BACK.dae" scale="1 1 1"/>
      </geometry>
      <material name="">
        <color rgba="1.0 0.0 0.0 1.0"/>
        <texture filename=""/>
      </material>
    </visual>
  </link>
  <joint name="J_RH_PARALLEL2" type="fixed">
    <origin xyz="1.424 0.0125 0.0"/>
    <parent link="RH_LEG"/>
    <child link="RH_KNUCKLE"/>
  </joint>
  <link name="RH_MOTOR">
    <inertial>
      <origin xyz="0.137 0.0 -0.012"/>
      <mass value="135.0"/>
      <inertia ixx="2.7945" ixy="0.0284" ixz="0.1825" iyy="5.1558" iyz="0.1494" izz="4.7264"/>
    </inertial>
    <visual>
      <origin xyz="0.0 0.0 0.0"/>
      <geometry>
        <mesh filename="meshes/MOTOR.dae" scale="1.0 1.0 1.0"/>
      </geometry>
    </visual>
  </link>
  <joint name="J_RH_STEER" type="fixed">
    <origin rpy="0.0 0.0 1.5707963267948966" xyz="0.05 0.3835 0.051"/>
    <parent link="RH_KNUCKLE"/>
    <child link="RH_MOTOR"/>
  </joint>
  <link name="RH_WHEEL">
    <inertial>
      <origin xyz="0.02 0.0 0.0"/>
      <mass value="420"/>
      <inertia ixx="72.4592" ixy="-0.0173" ixz="-0.0116" iyy="48.4413" iyz="0.017" izz="48.4413"/>
    </inertial>
    <visual>
      <origin xyz="0.0 0.0 0.0"/>
      <geometry>
        <mesh filename="meshes/WHEEL.dae" scale="1.0 1.0 1.0"/>
      </geometry>
      <material name="">
        <color rgba="1.0 0.0 0.0 1.0"/>
      </material>
    </visual>
    <collision>
      <origin xyz="0.0 0.0 0.0"/>
      <geometry>
        <sphere radius="0.6149438"/>
      </geometry>
    </collision>
  </link>
  <joint name="J_RH_WHEEL" type="fixed">
    <origin xyz="0.298 0.0 0.0"/>
    <parent link="RH_MOTOR"/>
    <child link="RH_WHEEL"/>
  </joint>
  <link name="LH_CLAW">
    <inertial>
      <origin xyz="0.627 0.007 0.094"/>
      <mass value="117.4"/>
      <inertia ixx="4.2263" ixy="1.2183" ixz="3.0811" iyy="63.3392" iyz="0.0680" izz="62.0039"/>
    </inertial>
    <visual name="">
      <origin xyz="0.0 0.0 0.0"/>
      <geometry>
        <mesh filename="meshes/CLAW.dae" scale="1.0 -1 1.0"/>
      </geometry>
    </visual>
  </link>
  <joint name="J_LH_CLAW" type="fixed">
    <origin rpy="0.0 0.0 -0.383" xyz="0.322 -0.0528 -0.05"/>
    <parent link="LH_KNUCKLE"/>
    <child link="LH_CLAW"/>
  </joint>
  <link name="RH_CLAW">
    <inertial>
      <origin xyz="0.627 0.007 0.094"/>
      <mass value="117.4"/>
      <inertia ixx="4.2263" ixy="1.2183" ixz="3.0811" iyy="63.3392" iyz="0.0680" izz="62.0039"/>
    </inertial>
    <visual name="">
      <origin xyz="0.0 0.0 0.0"/>
      <geometry>
        <mesh filename="meshes/CLAW.dae" scale="1.0 1 1.0"/>
      </geometry>
    </visual>
  </link>
  <joint name="J_RH_CLAW" type="fixed">
    <origin rpy="0.0 0.0 0.383" xyz="0.322 0.0528 -0.05"/>
    <parent link="RH_KNUCKLE"/>
    <child link="RH_CLAW"/>
  </joint>
  <link name="CABIN">
    <inertial>
      <origin xyz="-0.11 0.024 0.597"/>
      <mass value="3800.0"/>
      <inertia ixx="4080.990" ixy="57.6572" ixz="-534.1662" iyy="4284.21" iyz="292.7181" izz="2626.23"/>
    </inertial>
    <visual name="">
      <origin xyz="0.0 0.0 0.0"/>
      <geometry>
        <mesh filename="meshes/CABIN.dae" scale="1.0 1.0 1.0"/>
      </geometry>
      <material name="">
        <color rgba="1.0 0.0 0.0 1.0"/>
        <texture filename=""/>
      </material>
    </visual>
  </link>
  <!-- cabin slew fixed: EE is measured in the CABIN frame, so the arm is the same 4-DOF
       chain as the M545 (boom, stick, tele, pitch); J_TURN does not affect EE-in-CABIN. -->
  <joint name="J_TURN" type="fixed">
    <origin xyz="0.0 0.0 0.647"/>
    <parent link="BASE"/>
    <child link="CABIN"/>
  </joint>
  <link name="BOOM">
    <inertial>
      <origin xyz="1.154 0.002 0.173"/>
      <mass value="680.205"/>
      <inertia ixx="52.02" ixy="4.647" ixz="122.83" iyy="1442.86" iyz="0.026" izz="1389.3"/>
    </inertial>
    <visual name="">
      <origin xyz="0.0 0.0 0.0"/>
      <geometry>
        <mesh filename="meshes/BOOM.dae" scale="1.0 1.0 1.0"/>
      </geometry>
      <material name="">
        <color rgba="1.0 0.0 0.0 1.0"/>
        <texture filename=""/>
      </material>
    </visual>
  </link>
  <joint name="J_BOOM" type="revolute">
    <origin xyz="0.89 -0.274 0.23"/>
    <parent link="CABIN"/>
    <child link="BOOM"/>
    <axis xyz="0.0 1.0 0.0"/>
    <limit effort="0.0" lower="-1.38" upper="0.36" velocity="0.0"/>
  </joint>
  <link name="STICK">
    <inertial>
      <origin xyz="0.004 0.003 0.235"/>
      <mass value="476.2"/>
      <inertia ixx="44.432" ixy="1.06" ixz="10.862" iyy="242.44" iyz="0.588" izz="206.54"/>
    </inertial>
    <visual name="">
      <origin xyz="0.0 0.0 0.0"/>
      <geometry>
        <mesh filename="meshes/STICK.dae" scale="1.0 1.0 1.0"/>
      </geometry>
      <material name="">
        <color rgba="1.0 0.0 0.0 1.0"/>
        <texture filename=""/>
      </material>
    </visual>
  </link>
  <joint name="J_STICK" type="revolute">
    <origin xyz="2.53 0.0 0.0"/>
    <parent link="BOOM"/>
    <child link="STICK"/>
    <axis xyz="0.0 1.0 0.0"/>
    <limit effort="0.0" lower="0.59" upper="2.73" velocity="0.0"/>
  </joint>
  <link name="TELE">
    <inertial>
      <origin xyz="-0.286 0.019 0.167"/>
      <mass value="555.3"/>
      <inertia ixx="45.7167" ixy="-6.842" ixz="16.32" iyy="388.77" iyz="2.43" izz="353.6"/>
    </inertial>
    <visual name="">
      <origin xyz="0.0 0.0 0.0"/>
      <geometry>
        <mesh filename="meshes/TELE.dae" scale="1.0 1.0 1.0"/>
      </geometry>
      <material name="">
        <color rgba="1.0 0.0 0.0 1.0"/>
        <texture filename=""/>
      </material>
    </visual>
  </link>
  <joint name="J_TELE" type="prismatic">
    <origin xyz="0.925 0.0 0.356"/>
    <parent link="STICK"/>
    <child link="TELE"/>
    <axis xyz="1.0 0.0 0.0"/>
    <limit effort="0.0" lower="0.0" upper="1.598" velocity="0.0"/>
  </joint>
  <link name="ROTO_BASE">
    <inertial>
      <origin xyz="0.025 0.002 0.255"/>
      <mass value="161.89"/>
      <inertia ixx="23.37" ixy="-0.013" ixz="0.851" iyy="18.96" iyz="0.167" izz="11.02"/>
    </inertial>
    <visual name="">
      <origin xyz="0.0 0.0 0.0"/>
      <geometry>
        <mesh filename="meshes/ROTO_BASE.dae" scale="1.0 1.0 1.0"/>
      </geometry>
      <material name="">
        <color rgba="1.0 0.0 0.0 1.0"/>
        <texture filename=""/>
      </material>
    </visual>
  </link>
  <joint name="J_EE_PITCH" type="revolute">
    <origin xyz="0.9 0.0 0.011"/>
    <parent link="TELE"/>
    <child link="ROTO_BASE"/>
    <axis xyz="0.0 1.0 0.0"/>
    <limit effort="0.0" lower="-0.66" upper="2.298" velocity="0.0"/>
  </joint>
  <link name="ROTO_TILT">
    <inertial>
      <origin xyz="0.098 -0.014 0.005"/>
      <mass value="166.8"/>
      <inertia ixx="6.919" ixy="-0.189" ixz="0.145" iyy="4.53" iyz="-0.03" izz="6.365"/>
    </inertial>
    <visual name="">
      <origin rpy="-1.57 0.0 0.0" xyz="0.0 0.0 0.0"/>
      <geometry>
        <mesh filename="meshes/ROTO_TILT.dae" scale="1.0 1.0 1.0"/>
      </geometry>
      <material name="">
        <color rgba="1.0 0.0 0.0 1.0"/>
        <texture filename=""/>
      </material>
    </visual>
  </link>
  <joint name="J_EE_ROLL" type="fixed">
    <origin xyz="0.263 0.0 0.3645"/>
    <parent link="ROTO_BASE"/>
    <child link="ROTO_TILT"/>
  </joint>
  <link name="ROTO_YAW">
    <inertial>
      <origin xyz="0.025 0.0 -0.074"/>
      <mass value="95.3"/>
      <inertia ixx="1.629" ixy="0.0" ixz="-0.137" iyy="2.421" iyz="0.000" izz="2.376"/>
    </inertial>
    <visual name="">
      <origin rpy="0.0 -1.57 0.0" xyz="0.0 0.0 0.0"/>
      <geometry>
        <mesh filename="meshes/ROTO_YAW.dae" scale="1.0 1.0 1.0"/>
      </geometry>
      <material name="">
        <color rgba="1.0 0.0 0.0 1.0"/>
        <texture filename=""/>
      </material>
    </visual>
  </link>
  <joint name="J_EE_YAW" type="fixed">
    <origin xyz="0.1785 0.0225 0.0"/>
    <parent link="ROTO_TILT"/>
    <child link="ROTO_YAW"/>
  </joint>
  <link name="SHOVEL">
    <inertial>
      <origin rpy="0 0 0" xyz="0.15 0.00015 0.147"/>
      <mass value="480"/>
      <inertia ixx="90.956" ixy="-0.03157" ixz="-7.54324" iyy="70.6513" iyz="-0.01441" izz="70.6513"/>
    </inertial>
    <visual>
      <origin rpy="0 0 0" xyz="0 0 0"/>
      <geometry>
        <mesh filename="meshes/SHOVEL_1500.dae"/>
      </geometry>
    </visual>
    <collision>
      <origin xyz="0 0 0" rpy="0 0 0"/>
      <geometry>
        <mesh filename="meshes/SHOVEL_1500.dae"/>
      </geometry>
    </collision>
  </link>
  <joint name="J_ROTO2EE" type="fixed">
    <origin rpy="0.0 0.0 0.0" xyz="0.116 0.0 -0.149"/>
    <parent link="ROTO_YAW"/>
    <child link="SHOVEL"/>
    <limit effort="0.0" lower="0.0" upper="0.0" velocity="0.0"/>
  </joint>
  <link name="ENDEFFECTOR_CONTACT"/>
  <joint name="SHOVEL_TO_ENDEFFECTOR_CONTACT" type="fixed">
    <parent link="SHOVEL"/>
    <child link="ENDEFFECTOR_CONTACT"/>
    <origin rpy="0 -0.244 0" xyz="0.86 0 -0.14"/>
  </joint>
  <link name="shovel_back_center">
    <inertial>
      <origin xyz="0.0 0.0 0.0"/>
      <mass value="1"/>
      <inertia ixx="1" ixy="0" ixz="0" iyy="1" iyz="0" izz="1"/>
    </inertial>
  </link>
  <joint name="J_shovel_back_center" type="fixed">
    <parent link="ENDEFFECTOR_CONTACT"/>
    <child link="shovel_back_center"/>
    <origin xyz="0.044185 0.0 0.699031"/>
  </joint>
</robot>
